Workbook

Sheet Plantilla Invitados
A1: codigo | B1: nombre | C1: pases | D1: telefono | E1: grupo | F1: notas | G1: link_invitacion | H1: Columna1
A2: A001 | B2: Sandra A. Ruiz | C2: 2 | D2: 6861159998 | E2: FAMILIA | F2: Ejemplo de invitado | G2: =Config!$B$2&"?codigo="&A2 -> https://xvsandra.vercel.app/?codigo=A001
A3: A002 | B3: Fam. Ruiz Paredes | C3: 2 | D3: 6861138020 | G3: =Config!$B$2&"?codigo="&A3 -> https://xvsandra.vercel.app/?codigo=A002
A4: A003 | B4: Rogelio Ruiz | C4: 2 | D4: 6861876979 | G4: =Config!$B$2&"?codigo="&A4 -> https://xvsandra.vercel.app/?codigo=A003
A5: A004 | B5: Fam . Hansmann Ruiz | C5: 6 | D5: 6861707740 | G5: =IF(A5="","",Config!$B$2&"?codigo="&A5) -> https://xvsandra.vercel.app/?codigo=A004
A6: A005 | B6: Fam. Cárdenas Ruiz | C6: 5 | D6: 6861575026 | G6: =IF(A6="","",Config!$B$2&"?codigo="&A6) -> https://xvsandra.vercel.app/?codigo=A005
A7: A006 | B7: Adrián Valenzuela | C7: 2 | D7: 6866300023 | G7: =IF(A7="","",Config!$B$2&"?codigo="&A7) -> https://xvsandra.vercel.app/?codigo=A006
A8: A007 | B8: Fam. Rincón | C8: 3 | D8: 6863900811 | G8: =IF(A8="","",Config!$B$2&"?codigo="&A8) -> https://xvsandra.vercel.app/?codigo=A007
A9: A008 | B9: Sara Verdugo | C9: 2 | D9: 6862013354 | G9: =IF(A9="","",Config!$B$2&"?codigo="&A9) -> https://xvsandra.vercel.app/?codigo=A008 | H9: https://xvsandra.vercel.app/?codigo=A009
A10: A009 | B10: Fam. Ramirez Cota | C10: 2 | D10: 6861084117 | G10: =IF(A10="","",Config!$B$2&"?codigo="&A10) -> https://xvsandra.vercel.app/?codigo=A009
A11: A010 | B11: Junuen Gonzalez | C11: 1 | D11: 6643567391 | G11: =IF(A11="","",Config!$B$2&"?codigo="&A11) -> https://xvsandra.vercel.app/?codigo=A010
A12: A011 | B12: Elsa Miramón | C12: 1 | D12: 6862485631 | G12: =IF(A12="","",Config!$B$2&"?codigo="&A12) -> https://xvsandra.vercel.app/?codigo=A011
A13: A012 | B13: Elena Gonzalez | C13: 1 | D13: 6862412292 | G13: =IF(A13="","",Config!$B$2&"?codigo="&A13) -> https://xvsandra.vercel.app/?codigo=A012
A14: A013 | B14: Erika Marquez | C14: 1 | D14: 6862434748 | G14: =IF(A14="","",Config!$B$2&"?codigo="&A14) -> https://xvsandra.vercel.app/?codigo=A013
A15: A014 | B15: Jesús y Wendy Montes | C15: 2 | D15: 6863150447 | G15: =IF(A15="","",Config!$B$2&"?codigo="&A15) -> https://xvsandra.vercel.app/?codigo=A014
A16: A015 | B16: Oscar y Nelly Villegas | C16: 2 | D16: 6862710014 | G16: =IF(A16="","",Config!$B$2&"?codigo="&A16) -> https://xvsandra.vercel.app/?codigo=A015
A17: A016 | B17: Joel y Claudia Jimenez | C17: 2 | D17: 6869462795 | G17: =IF(A17="","",Config!$B$2&"?codigo="&A17) -> https://xvsandra.vercel.app/?codigo=A016
A18: A017 | B18: Aleida Rojas | C18: 2 | D18: 6861634661 | G18: =IF(A18="","",Config!$B$2&"?codigo="&A18) -> https://xvsandra.vercel.app/?codigo=A017
A19: A018 | B19: Veronica Cruz | C19: 1 | D19: 6861858868 | G19: =IF(A19="","",Config!$B$2&"?codigo="&A19) -> https://xvsandra.vercel.app/?codigo=A018
A20: A019 | B20: Gonzalo y Silvia Rosales | C20: 2 | G20: =IF(A20="","",Config!$B$2&"?codigo="&A20) -> https://xvsandra.vercel.app/?codigo=A019
A21: A020 | B21: Camila García | C21: 1 | G21: =IF(A21="","",Config!$B$2&"?codigo="&A21) -> https://xvsandra.vercel.app/?codigo=A020
A22: A021 | B22: Ximena García | C22: 1 | G22: =IF(A22="","",Config!$B$2&"?codigo="&A22) -> https://xvsandra.vercel.app/?codigo=A021
A23: A022 | B23: Dulce Villegas | C23: 1 | G23: =IF(A23="","",Config!$B$2&"?codigo="&A23) -> https://xvsandra.vercel.app/?codigo=A022
A24: A023 | B24: Alexa Campos | C24: 1 | G24: =IF(A24="","",Config!$B$2&"?codigo="&A24) -> https://xvsandra.vercel.app/?codigo=A023
A25: A024 | B25: Angela Martinéz | C25: 1 | G25: =IF(A25="","",Config!$B$2&"?codigo="&A25) -> https://xvsandra.vercel.app/?codigo=A024
A26: A025 | B26: Vanessa Magaña | C26: 1 | G26: =IF(A26="","",Config!$B$2&"?codigo="&A26) -> https://xvsandra.vercel.app/?codigo=A025
A27: A026 | B27: Yuliana García | C27: 1 | G27: =IF(A27="","",Config!$B$2&"?codigo="&A27) -> https://xvsandra.vercel.app/?codigo=A026
A28: A027 | B28: Isabella Curiel | C28: 1 | G28: =IF(A28="","",Config!$B$2&"?codigo="&A28) -> https://xvsandra.vercel.app/?codigo=A027
A29: A028 | B29: Isaac Jimenez | C29: 1 | G29: =IF(A29="","",Config!$B$2&"?codigo="&A29) -> https://xvsandra.vercel.app/?codigo=A028
A30: A029 | B30: Salvador Vázquez | C30: 1 | G30: =IF(A30="","",Config!$B$2&"?codigo="&A30) -> https://xvsandra.vercel.app/?codigo=A029
A31: A030 | B31: Daniel Alvarado | C31: 1 | G31: =IF(A31="","",Config!$B$2&"?codigo="&A31) -> https://xvsandra.vercel.app/?codigo=A030
... A66: A065 | B66: Sugey Diaz | C66: 1 | G66: =IF(A66="","",Config!$B$2&"?codigo="&A66) -> https://xvsandra.vercel.app/?codigo=A065
G67: =IF(A67="","",Config!$B$2&"?codigo="&A67)
G68: =IF(A68="","",Config!$B$2&"?codigo="&A68)
G69: =IF(A69="","",Config!$B$2&"?codigo="&A69)
G70: =IF(A70="","",Config!$B$2&"?codigo="&A70)
G71: =IF(A71="","",Config!$B$2&"?codigo="&A71)
G72: =IF(A72="","",Config!$B$2&"?codigo="&A72)
G73: =IF(A73="","",Config!$B$2&"?codigo="&A73)
G74: =IF(A74="","",Config!$B$2&"?codigo="&A74)
...

Sheet Config
A1: Configuración
A2: URL base de la invitación | B2: https://xvsandra.vercel.app/
A3: Ejemplo de uso | B3: Cambia la URL base cuando tengas tu link final de Vercel
A5: Grupos sugeridos | B5: Familia mamá
B6: Familia papá
B7: Amigos
B8: Escuela
B9: Trabajo
B10: Otros

Sheet Instrucciones
A1: Instrucciones para plantilla de invitados
A3: Paso | B3: Qué hacer | C3: Ejemplo | D3: Notas
A4: 1 | B4: Captura un código único por invitado | C4: A001 | D4: No repitas códigos.
A5: 2 | B5: Escribe el nombre como aparecerá en la invitación | C5: Familia Ruiz | D5: Este nombre se mostrará en el RSVP.
A6: 3 | B6: Asigna número de pases | C6: 5 | D6: Debe ser número entero.
A7: 4 | B7: Agrega teléfono si lo tienes | C7: 6861234567 | D7: Opcional.
A8: 5 | B8: Clasifica por grupo | C8: Familia mamá | D8: Opcional; ayuda a filtrar.
A9: 6 | B9: Revisa el link generado | C9: https://.../?codigo=A001 | D9: Este link se enviará al invitado.
A10: 7 | B10: Cuando la lista esté completa, la importamos a Firebase | D10: No cambies los nombres de columnas.
A12: Colecciones Firebase | B12: invitados / confirmaciones / libroVisitas
